{"uuid": "2d041abb-51d0-4f7d-9e38-a726256b4584", "children": ["88b1eeeb-f54b-41dd-a31d-04216699702f", "f1809a3f-e911-4b77-8dbd-44a5bd42d7e2", "6455ff43-132c-45f7-a8fe-72809c5f4d9d"], "befores": [{"name": "initialize_test", "status": "passed", "start": 1699536645450, "stop": 1699536645450}], "afters": [{"name": "initialize_test::0", "status": "broken", "statusDetails": {"message": "urllib3.exceptions.MaxRetryError: HTTPConnectionPool(host='localhost', port=59760): Max retries exceeded with url: /session/b11c5db94eb4b00bf5ad946d8c85278f/window (Caused by NewConnectionError('<urllib3.connection.HTTPConnection object at 0x10b51a3d0>: Failed to establish a new connection: [Errno 61] Connection refused'))\n", "trace": "  File \"/Users/DerekPetersen/PycharmProjects/CIG/venv/lib/python3.9/site-packages/allure_commons/_allure.py\", line 221, in __call__\n    return self._fixture_function(*args, **kwargs)\n  File \"/Users/DerekPetersen/PycharmProjects/CIG/venv/lib/python3.9/site-packages/_pytest/fixtures.py\", line 911, in _teardown_yield_fixture\n    next(it)\n  File \"/Users/DerekPetersen/PycharmProjects/CIG/conftest.py\", line 10, in initialize_test\n    base_page.get_driver().close()\n  File \"/Users/DerekPetersen/PycharmProjects/CIG/venv/lib/python3.9/site-packages/selenium/webdriver/remote/webdriver.py\", line 455, in close\n    self.execute(Command.CLOSE)\n  File \"/Users/DerekPetersen/PycharmProjects/CIG/venv/lib/python3.9/site-packages/selenium/webdriver/remote/webdriver.py\", line 342, in execute\n    response = self.command_executor.execute(driver_command, params)\n  File \"/Users/DerekPetersen/PycharmProjects/CIG/venv/lib/python3.9/site-packages/selenium/webdriver/remote/remote_connection.py\", line 297, in execute\n    return self._request(command_info[0], url, body=data)\n  File \"/Users/DerekPetersen/PycharmProjects/CIG/venv/lib/python3.9/site-packages/selenium/webdriver/remote/remote_connection.py\", line 318, in _request\n    response = self._conn.request(method, url, body=body, headers=headers)\n  File \"/Users/DerekPetersen/PycharmProjects/CIG/venv/lib/python3.9/site-packages/urllib3/_request_methods.py\", line 110, in request\n    return self.request_encode_url(\n  File \"/Users/DerekPetersen/PycharmProjects/CIG/venv/lib/python3.9/site-packages/urllib3/_request_methods.py\", line 143, in request_encode_url\n    return self.urlopen(method, url, **extra_kw)\n  File \"/Users/DerekPetersen/PycharmProjects/CIG/venv/lib/python3.9/site-packages/urllib3/poolmanager.py\", line 443, in urlopen\n    response = conn.urlopen(method, u.request_uri, **kw)\n  File \"/Users/DerekPetersen/PycharmProjects/CIG/venv/lib/python3.9/site-packages/urllib3/connectionpool.py\", line 874, in urlopen\n    return self.urlopen(\n  File \"/Users/DerekPetersen/PycharmProjects/CIG/venv/lib/python3.9/site-packages/urllib3/connectionpool.py\", line 874, in urlopen\n    return self.urlopen(\n  File \"/Users/DerekPetersen/PycharmProjects/CIG/venv/lib/python3.9/site-packages/urllib3/connectionpool.py\", line 874, in urlopen\n    return self.urlopen(\n  File \"/Users/DerekPetersen/PycharmProjects/CIG/venv/lib/python3.9/site-packages/urllib3/connectionpool.py\", line 844, in urlopen\n    retries = retries.increment(\n  File \"/Users/DerekPetersen/PycharmProjects/CIG/venv/lib/python3.9/site-packages/urllib3/util/retry.py\", line 515, in increment\n    raise MaxRetryError(_pool, url, reason) from reason  # type: ignore[arg-type]\n"}, "start": 1699536649316, "stop": 1699536649324}], "start": 1699536645450, "stop": 1699536649324}