{"uuid": "5c018678-f878-457e-b078-b05624a7b5e7", "children": ["6455ff43-132c-45f7-a8fe-72809c5f4d9d"], "befores": [{"name": "start_and_clean", "status": "broken", "statusDetails": {"message": "urllib3.exceptions.MaxRetryError: HTTPConnectionPool(host='localhost', port=59760): Max retries exceeded with url: /session/b11c5db94eb4b00bf5ad946d8c85278f/url (Caused by NewConnectionError('<urllib3.connection.HTTPConnection object at 0x10b4719d0>: Failed to establish a new connection: [Errno 61] Connection refused'))\n", "trace": "  File \"/Users/DerekPetersen/PycharmProjects/CIG/venv/lib/python3.9/site-packages/pluggy/_callers.py\", line 77, in _multicall\n    res = hook_impl.function(*args)\n  File \"/Users/DerekPetersen/PycharmProjects/CIG/venv/lib/python3.9/site-packages/_pytest/fixtures.py\", line 1123, in pytest_fixture_setup\n    result = call_fixture_func(fixturefunc, request, kwargs)\n  File \"/Users/DerekPetersen/PycharmProjects/CIG/venv/lib/python3.9/site-packages/_pytest/fixtures.py\", line 895, in call_fixture_func\n    fixture_result = next(generator)\n  File \"/Users/DerekPetersen/PycharmProjects/CIG/tests/ui/test_search.py\", line 24, in start_and_clean\n    self.go_to_homepage()\n  File \"/Users/DerekPetersen/PycharmProjects/CIG/venv/lib/python3.9/site-packages/allure_commons/_allure.py\", line 192, in impl\n    return func(*a, **kw)\n  File \"/Users/DerekPetersen/PycharmProjects/CIG/tests/ui/test_search.py\", line 20, in go_to_homepage\n    self.webdriver.go_to_home_page()\n  File \"/Users/DerekPetersen/PycharmProjects/CIG/webdriver/web_driver.py\", line 19, in go_to_home_page\n    self.driver.get(self.url)\n  File \"/Users/DerekPetersen/PycharmProjects/CIG/venv/lib/python3.9/site-packages/selenium/webdriver/remote/webdriver.py\", line 353, in get\n    self.execute(Command.GET, {\"url\": url})\n  File \"/Users/DerekPetersen/PycharmProjects/CIG/venv/lib/python3.9/site-packages/selenium/webdriver/remote/webdriver.py\", line 342, in execute\n    response = self.command_executor.execute(driver_command, params)\n  File \"/Users/DerekPetersen/PycharmProjects/CIG/venv/lib/python3.9/site-packages/selenium/webdriver/remote/remote_connection.py\", line 297, in execute\n    return self._request(command_info[0], url, body=data)\n  File \"/Users/DerekPetersen/PycharmProjects/CIG/venv/lib/python3.9/site-packages/selenium/webdriver/remote/remote_connection.py\", line 318, in _request\n    response = self._conn.request(method, url, body=body, headers=headers)\n  File \"/Users/DerekPetersen/PycharmProjects/CIG/venv/lib/python3.9/site-packages/urllib3/_request_methods.py\", line 118, in request\n    return self.request_encode_body(\n  File \"/Users/DerekPetersen/PycharmProjects/CIG/venv/lib/python3.9/site-packages/urllib3/_request_methods.py\", line 217, in request_encode_body\n    return self.urlopen(method, url, **extra_kw)\n  File \"/Users/DerekPetersen/PycharmProjects/CIG/venv/lib/python3.9/site-packages/urllib3/poolmanager.py\", line 443, in urlopen\n    response = conn.urlopen(method, u.request_uri, **kw)\n  File \"/Users/DerekPetersen/PycharmProjects/CIG/venv/lib/python3.9/site-packages/urllib3/connectionpool.py\", line 874, in urlopen\n    return self.urlopen(\n  File \"/Users/DerekPetersen/PycharmProjects/CIG/venv/lib/python3.9/site-packages/urllib3/connectionpool.py\", line 874, in urlopen\n    return self.urlopen(\n  File \"/Users/DerekPetersen/PycharmProjects/CIG/venv/lib/python3.9/site-packages/urllib3/connectionpool.py\", line 874, in urlopen\n    return self.urlopen(\n  File \"/Users/DerekPetersen/PycharmProjects/CIG/venv/lib/python3.9/site-packages/urllib3/connectionpool.py\", line 844, in urlopen\n    retries = retries.increment(\n  File \"/Users/DerekPetersen/PycharmProjects/CIG/venv/lib/python3.9/site-packages/urllib3/util/retry.py\", line 515, in increment\n    raise MaxRetryError(_pool, url, reason) from reason  # type: ignore[arg-type]\n"}, "steps": [{"name": "Going to homepage", "status": "broken", "statusDetails": {"message": "urllib3.exceptions.MaxRetryError: HTTPConnectionPool(host='localhost', port=59760): Max retries exceeded with url: /session/b11c5db94eb4b00bf5ad946d8c85278f/url (Caused by NewConnectionError('<urllib3.connection.HTTPConnection object at 0x10b4719d0>: Failed to establish a new connection: [Errno 61] Connection refused'))\n", "trace": "  File \"/Users/DerekPetersen/PycharmProjects/CIG/venv/lib/python3.9/site-packages/allure_commons/_allure.py\", line 192, in impl\n    return func(*a, **kw)\n  File \"/Users/DerekPetersen/PycharmProjects/CIG/tests/ui/test_search.py\", line 20, in go_to_homepage\n    self.webdriver.go_to_home_page()\n  File \"/Users/DerekPetersen/PycharmProjects/CIG/webdriver/web_driver.py\", line 19, in go_to_home_page\n    self.driver.get(self.url)\n  File \"/Users/DerekPetersen/PycharmProjects/CIG/venv/lib/python3.9/site-packages/selenium/webdriver/remote/webdriver.py\", line 353, in get\n    self.execute(Command.GET, {\"url\": url})\n  File \"/Users/DerekPetersen/PycharmProjects/CIG/venv/lib/python3.9/site-packages/selenium/webdriver/remote/webdriver.py\", line 342, in execute\n    response = self.command_executor.execute(driver_command, params)\n  File \"/Users/DerekPetersen/PycharmProjects/CIG/venv/lib/python3.9/site-packages/selenium/webdriver/remote/remote_connection.py\", line 297, in execute\n    return self._request(command_info[0], url, body=data)\n  File \"/Users/DerekPetersen/PycharmProjects/CIG/venv/lib/python3.9/site-packages/selenium/webdriver/remote/remote_connection.py\", line 318, in _request\n    response = self._conn.request(method, url, body=body, headers=headers)\n  File \"/Users/DerekPetersen/PycharmProjects/CIG/venv/lib/python3.9/site-packages/urllib3/_request_methods.py\", line 118, in request\n    return self.request_encode_body(\n  File \"/Users/DerekPetersen/PycharmProjects/CIG/venv/lib/python3.9/site-packages/urllib3/_request_methods.py\", line 217, in request_encode_body\n    return self.urlopen(method, url, **extra_kw)\n  File \"/Users/DerekPetersen/PycharmProjects/CIG/venv/lib/python3.9/site-packages/urllib3/poolmanager.py\", line 443, in urlopen\n    response = conn.urlopen(method, u.request_uri, **kw)\n  File \"/Users/DerekPetersen/PycharmProjects/CIG/venv/lib/python3.9/site-packages/urllib3/connectionpool.py\", line 874, in urlopen\n    return self.urlopen(\n  File \"/Users/DerekPetersen/PycharmProjects/CIG/venv/lib/python3.9/site-packages/urllib3/connectionpool.py\", line 874, in urlopen\n    return self.urlopen(\n  File \"/Users/DerekPetersen/PycharmProjects/CIG/venv/lib/python3.9/site-packages/urllib3/connectionpool.py\", line 874, in urlopen\n    return self.urlopen(\n  File \"/Users/DerekPetersen/PycharmProjects/CIG/venv/lib/python3.9/site-packages/urllib3/connectionpool.py\", line 844, in urlopen\n    retries = retries.increment(\n  File \"/Users/DerekPetersen/PycharmProjects/CIG/venv/lib/python3.9/site-packages/urllib3/util/retry.py\", line 515, in increment\n    raise MaxRetryError(_pool, url, reason) from reason  # type: ignore[arg-type]\n"}, "start": 1699536649125, "stop": 1699536649130}], "start": 1699536649125, "stop": 1699536649130}], "start": 1699536649125, "stop": 1699536649315}